2025-01-10 19:34:06,832 [MainProcess: 15180] [MainThread: 9932] [INFO] uvicorn.error: Will watch for changes in these directories: ['C:\\Users\\giann\\Desktop\\seismo-website\\fastapiapp']
2025-01-10 19:34:06,838 [MainProcess: 15180] [MainThread: 9932] [INFO] uvicorn.error: Uvicorn running on http://127.0.0.1:8000 (Press CTRL+C to quit)
2025-01-10 19:34:06,838 [MainProcess: 15180] [MainThread: 9932] [INFO] uvicorn.error: Started reloader process [15180] using WatchFiles
2025-01-10 19:34:08,714 [SpawnProcess-1: 22416] [MainThread: 10084] [INFO] uvicorn.error: Started server process [22416]
2025-01-10 19:34:08,714 [SpawnProcess-1: 22416] [MainThread: 10084] [INFO] uvicorn.error: Waiting for application startup.
2025-01-10 19:34:08,714 [SpawnProcess-1: 22416] [MainThread: 10084] [TRACE] uvicorn.asgi: ASGI [1] Started scope={'type': 'lifespan', 'asgi': {'version': '3.0', 'spec_version': '2.0'}, 'state': {}}
2025-01-10 19:34:08,718 [SpawnProcess-1: 22416] [MainThread: 10084] [TRACE] uvicorn.asgi: ASGI [1] Receive {'type': 'lifespan.startup'}
2025-01-10 19:34:08,718 [SpawnProcess-1: 22416] [MainThread: 10084] [TRACE] uvicorn.asgi: ASGI [1] Send {'type': 'lifespan.startup.complete'}
2025-01-10 19:34:08,718 [SpawnProcess-1: 22416] [MainThread: 10084] [INFO] uvicorn.error: Application startup complete.
2025-01-10 19:34:40,714 [MainProcess: 15180] [MainThread: 9932] [WARNING] uvicorn.error: WatchFiles detected changes in 'main.py'. Reloading...
2025-01-10 19:34:40,794 [SpawnProcess-1: 22416] [MainThread: 10084] [INFO] uvicorn.error: Shutting down
2025-01-10 19:34:40,909 [SpawnProcess-1: 22416] [MainThread: 10084] [INFO] uvicorn.error: Waiting for application shutdown.
2025-01-10 19:34:40,910 [SpawnProcess-1: 22416] [MainThread: 10084] [TRACE] uvicorn.asgi: ASGI [1] Receive {'type': 'lifespan.shutdown'}
2025-01-10 19:34:40,912 [SpawnProcess-1: 22416] [MainThread: 10084] [TRACE] uvicorn.asgi: ASGI [1] Send {'type': 'lifespan.shutdown.complete'}
2025-01-10 19:34:40,917 [SpawnProcess-1: 22416] [MainThread: 10084] [TRACE] uvicorn.asgi: ASGI [1] Completed
2025-01-10 19:34:40,917 [SpawnProcess-1: 22416] [MainThread: 10084] [INFO] uvicorn.error: Application shutdown complete.
2025-01-10 19:34:40,917 [SpawnProcess-1: 22416] [MainThread: 10084] [INFO] uvicorn.error: Finished server process [22416]
2025-01-10 19:34:43,357 [SpawnProcess-2: 9100] [MainThread: 25560] [INFO] uvicorn.error: Started server process [9100]
2025-01-10 19:34:43,366 [SpawnProcess-2: 9100] [MainThread: 25560] [INFO] uvicorn.error: Waiting for application startup.
2025-01-10 19:34:43,367 [SpawnProcess-2: 9100] [MainThread: 25560] [TRACE] uvicorn.asgi: ASGI [1] Started scope={'type': 'lifespan', 'asgi': {'version': '3.0', 'spec_version': '2.0'}, 'state': {}}
2025-01-10 19:34:43,367 [SpawnProcess-2: 9100] [MainThread: 25560] [TRACE] uvicorn.asgi: ASGI [1] Receive {'type': 'lifespan.startup'}
2025-01-10 19:34:43,368 [SpawnProcess-2: 9100] [MainThread: 25560] [TRACE] uvicorn.asgi: ASGI [1] Send {'type': 'lifespan.startup.complete'}
2025-01-10 19:34:43,368 [SpawnProcess-2: 9100] [MainThread: 25560] [INFO] uvicorn.error: Application startup complete.
2025-01-10 19:34:49,925 [SpawnProcess-2: 9100] [MainThread: 25560] [INFO] uvicorn.error: Shutting down
2025-01-10 19:34:50,026 [SpawnProcess-2: 9100] [MainThread: 25560] [INFO] uvicorn.error: Finished server process [9100]
2025-01-10 19:34:50,116 [SpawnProcess-2: 9100] [MainThread: 25560] [TRACE] uvicorn.asgi: ASGI [1] Send {'type': 'lifespan.shutdown.failed', 'message': 'Traceback (most recent call last):\n  File "C:\\Users\\giann\\anaconda3\\Lib\\asyncio\\runners.py", line 190, in run\n    return runner.run(main)\n           ^^^^^^^^^^^^^^^^\n  File "C:\\Users\\giann\\anaconda3\\Lib\\asyncio\\runners.py", line 118, in run\n    return self._loop.run_until_complete(task)\n           ^^^^^^^^^^^^^^^^^^^^^^^^^^^^^^^^^^^\n  File "C:\\Users\\giann\\anaconda3\\Lib\\asyncio\\base_events.py", line 641, in run_until_complete\n    self.run_forever()\n  File "C:\\Users\\giann\\anaconda3\\Lib\\asyncio\\base_events.py", line 608, in run_forever\n    self._run_once()\n  File "C:\\Users\\giann\\anaconda3\\Lib\\asyncio\\base_events.py", line 1936, in _run_once\n    handle._run()\n  File "C:\\Users\\giann\\anaconda3\\Lib\\asyncio\\events.py", line 84, in _run\n    self._context.run(self._callback, *self._args)\n  File "C:\\Users\\giann\\Desktop\\seismo-website\\fastapiapp\\.venv\\Lib\\site-packages\\uvicorn\\server.py", line 68, in serve\n    with self.capture_signals():\n  File "C:\\Users\\giann\\anaconda3\\Lib\\contextlib.py", line 144, in __exit__\n    next(self.gen)\n  File "C:\\Users\\giann\\Desktop\\seismo-website\\fastapiapp\\.venv\\Lib\\site-packages\\uvicorn\\server.py", line 332, in capture_signals\n    signal.raise_signal(captured_signal)\n  File "C:\\Users\\giann\\anaconda3\\Lib\\asyncio\\runners.py", line 157, in _on_sigint\n    raise KeyboardInterrupt()\nKeyboardInterrupt\n\nDuring handling of the above exception, another exception occurred:\n\nTraceback (most recent call last):\n  File "C:\\Users\\giann\\Desktop\\seismo-website\\fastapiapp\\.venv\\Lib\\site-packages\\starlette\\routing.py", line 700, in lifespan\n    await receive()\n  File "C:\\Users\\giann\\Desktop\\seismo-website\\fastapiapp\\.venv\\Lib\\site-packages\\uvicorn\\middleware\\message_logger.py", line 60, in inner_receive\n    message = await receive()\n              ^^^^^^^^^^^^^^^\n  File "C:\\Users\\giann\\Desktop\\seismo-website\\fastapiapp\\.venv\\Lib\\site-packages\\uvicorn\\lifespan\\on.py", line 137, in receive\n    return await self.receive_queue.get()\n           ^^^^^^^^^^^^^^^^^^^^^^^^^^^^^^\n  File "C:\\Users\\giann\\anaconda3\\Lib\\asyncio\\queues.py", line 158, in get\n    await getter\nasyncio.exceptions.CancelledError\n'}
2025-01-10 19:34:50,116 [SpawnProcess-2: 9100] [MainThread: 25560] [ERROR] uvicorn.error: Traceback (most recent call last):
  File "C:\Users\giann\anaconda3\Lib\asyncio\runners.py", line 190, in run
    return runner.run(main)
           ^^^^^^^^^^^^^^^^
  File "C:\Users\giann\anaconda3\Lib\asyncio\runners.py", line 118, in run
    return self._loop.run_until_complete(task)
           ^^^^^^^^^^^^^^^^^^^^^^^^^^^^^^^^^^^
  File "C:\Users\giann\anaconda3\Lib\asyncio\base_events.py", line 641, in run_until_complete
    self.run_forever()
  File "C:\Users\giann\anaconda3\Lib\asyncio\base_events.py", line 608, in run_forever
    self._run_once()
  File "C:\Users\giann\anaconda3\Lib\asyncio\base_events.py", line 1936, in _run_once
    handle._run()
  File "C:\Users\giann\anaconda3\Lib\asyncio\events.py", line 84, in _run
    self._context.run(self._callback, *self._args)
  File "C:\Users\giann\Desktop\seismo-website\fastapiapp\.venv\Lib\site-packages\uvicorn\server.py", line 68, in serve
    with self.capture_signals():
  File "C:\Users\giann\anaconda3\Lib\contextlib.py", line 144, in __exit__
    next(self.gen)
  File "C:\Users\giann\Desktop\seismo-website\fastapiapp\.venv\Lib\site-packages\uvicorn\server.py", line 332, in capture_signals
    signal.raise_signal(captured_signal)
  File "C:\Users\giann\anaconda3\Lib\asyncio\runners.py", line 157, in _on_sigint
    raise KeyboardInterrupt()
KeyboardInterrupt

During handling of the above exception, another exception occurred:

Traceback (most recent call last):
  File "C:\Users\giann\Desktop\seismo-website\fastapiapp\.venv\Lib\site-packages\starlette\routing.py", line 700, in lifespan
    await receive()
  File "C:\Users\giann\Desktop\seismo-website\fastapiapp\.venv\Lib\site-packages\uvicorn\middleware\message_logger.py", line 60, in inner_receive
    message = await receive()
              ^^^^^^^^^^^^^^^
  File "C:\Users\giann\Desktop\seismo-website\fastapiapp\.venv\Lib\site-packages\uvicorn\lifespan\on.py", line 137, in receive
    return await self.receive_queue.get()
           ^^^^^^^^^^^^^^^^^^^^^^^^^^^^^^
  File "C:\Users\giann\anaconda3\Lib\asyncio\queues.py", line 158, in get
    await getter
asyncio.exceptions.CancelledError

2025-01-10 19:34:50,125 [SpawnProcess-2: 9100] [MainThread: 25560] [TRACE] uvicorn.asgi: ASGI [1] Raised exception
2025-01-10 19:34:50,191 [MainProcess: 15180] [MainThread: 9932] [INFO] uvicorn.error: Stopping reloader process [15180]
